Workbook

Sheet شنبه
C5: گزارش روزانه
H7: موضوع | I7: فعالیت پیش بینی شده | J7: مقدار فعالیت | K7: میزان تفاوت
A8: شنبه | C8: 1404/8/1 | H8: خواب شب | J8: =SUMIF(Table1171921232527[موضوع],Table226810121416182022242628[[#This Row],[موضوع]],Table1171921232527[مقدار به دقیقه]) -> 0 | K8: =IF( OR(Table226810121416182022242628[[#This Row],[مقدار فعالیت]]=0,Table226810121416182022242628[[#This Row],[فعالیت پیش بینی شده]]=0),0,Table226810121416182022242628[[#This Row],[مقدار فعالیت]]-Table226810121416182022242628[[#This Row],[فعالیت پیش بینی شده]]) -> 0
A9: ساعت شروع | B9: ساعت پایان | C9: مقدار به دقیقه | D9: موضوع | E9: توضیحات | F9: مقدار به ساعت | H9: غذا خوردن | J9: =SUMIF(Table1171921232527[موضوع],Table226810121416182022242628[[#This Row],[موضوع]],Table1171921232527[مقدار به دقیقه]) -> 0 | K9: =IF( OR(Table226810121416182022242628[[#This Row],[مقدار فعالیت]]=0,Table226810121416182022242628[[#This Row],[فعالیت پیش بینی شده]]=0),0,Table226810121416182022242628[[#This Row],[مقدار فعالیت]]-Table226810121416182022242628[[#This Row],[فعالیت پیش بینی شده]]) -> 0
C10: =IF(OR(A10="",B10=""),"",IF(B10>=A10,(B10-A10)*24*60,(B10-A10+1)*24*60)) | F10: =IF(OR(A10="",B10=""),"",MOD(B10-A10,1)) | H10: رفت و آمد | J10: =SUMIF(Table1171921232527[موضوع],Table226810121416182022242628[[#This Row],[موضوع]],Table1171921232527[مقدار به دقیقه]) -> 0 | K10: =IF( OR(Table226810121416182022242628[[#This Row],[مقدار فعالیت]]=0,Table226810121416182022242628[[#This Row],[فعالیت پیش بینی شده]]=0),0,Table226810121416182022242628[[#This Row],[مقدار فعالیت]]-Table226810121416182022242628[[#This Row],[فعالیت پیش بینی شده]]) -> 0
C11: =IF(OR(A11="",B11=""),"",IF(B11>=A11,(B11-A11)*24*60,(B11-A11+1)*24*60)) | F11: =IF(OR(A11="",B11=""),"",MOD(B11-A11,1)) | H11: پروژه | J11: =SUMIF(Table1171921232527[موضوع],Table226810121416182022242628[[#This Row],[موضوع]],Table1171921232527[مقدار به دقیقه]) -> 0 | K11: =IF( OR(Table226810121416182022242628[[#This Row],[مقدار فعالیت]]=0,Table226810121416182022242628[[#This Row],[فعالیت پیش بینی شده]]=0),0,Table226810121416182022242628[[#This Row],[مقدار فعالیت]]-Table226810121416182022242628[[#This Row],[فعالیت پیش بینی شده]]) -> 0
C12: =IF(OR(A12="",B12=""),"",IF(B12>=A12,(B12-A12)*24*60,(B12-A12+1)*24*60)) | F12: =IF(OR(A12="",B12=""),"",MOD(B12-A12,1)) | H12: مطالعه | J12: =SUMIF(Table1171921232527[موضوع],Table226810121416182022242628[[#This Row],[موضوع]],Table1171921232527[مقدار به دقیقه]) -> 0 | K12: =IF( OR(Table226810121416182022242628[[#This Row],[مقدار فعالیت]]=0,Table226810121416182022242628[[#This Row],[فعالیت پیش بینی شده]]=0),0,Table226810121416182022242628[[#This Row],[مقدار فعالیت]]-Table226810121416182022242628[[#This Row],[فعالیت پیش بینی شده]]) -> 0
C13: =IF(OR(A13="",B13=""),"",IF(B13>=A13,(B13-A13)*24*60,(B13-A13+1)*24*60)) | F13: =IF(OR(A13="",B13=""),"",MOD(B13-A13,1)) | H13: دیدن ویدیو آموزشی | J13: =SUMIF(Table1171921232527[موضوع],Table226810121416182022242628[[#This Row],[موضوع]],Table1171921232527[مقدار به دقیقه]) -> 0 | K13: =IF( OR(Table226810121416182022242628[[#This Row],[مقدار فعالیت]]=0,Table226810121416182022242628[[#This Row],[فعالیت پیش بینی شده]]=0),0,Table226810121416182022242628[[#This Row],[مقدار فعالیت]]-Table226810121416182022242628[[#This Row],[فعالیت پیش بینی شده]]) -> 0
C14: =IF(OR(A14="",B14=""),"",IF(B14>=A14,(B14-A14)*24*60,(B14-A14+1)*24*60)) | F14: =IF(OR(A14="",B14=""),"",MOD(B14-A14,1)) | H14: مکتب | J14: =SUMIF(Table1171921232527[موضوع],Table226810121416182022242628[[#This Row],[موضوع]],Table1171921232527[مقدار به دقیقه]) -> 0 | K14: =IF( OR(Table226810121416182022242628[[#This Row],[مقدار فعالیت]]=0,Table226810121416182022242628[[#This Row],[فعالیت پیش بینی شده]]=0),0,Table226810121416182022242628[[#This Row],[مقدار فعالیت]]-Table226810121416182022242628[[#This Row],[فعالیت پیش بینی شده]]) -> 0
C15: =IF(OR(A15="",B15=""),"",IF(B15>=A15,(B15-A15)*24*60,(B15-A15+1)*24*60)) | F15: =IF(OR(A15="",B15=""),"",MOD(B15-A15,1)) | H15: استراحت | J15: =SUMIF(Table1171921232527[موضوع],Table226810121416182022242628[[#This Row],[موضوع]],Table1171921232527[مقدار به دقیقه]) -> 0 | K15: =IF( OR(Table226810121416182022242628[[#This Row],[مقدار فعالیت]]=0,Table226810121416182022242628[[#This Row],[فعالیت پیش بینی شده]]=0),0,Table226810121416182022242628[[#This Row],[مقدار فعالیت]]-Table226810121416182022242628[[#This Row],[فعالیت پیش بینی شده]]) -> 0
C16: =IF(OR(A16="",B16=""),"",IF(B16>=A16,(B16-A16)*24*60,(B16-A16+1)*24*60)) | F16: =IF(OR(A16="",B16=""),"",MOD(B16-A16,1)) | H16: متفرقه | J16: =SUMIF(Table1171921232527[موضوع],Table226810121416182022242628[[#This Row],[موضوع]],Table1171921232527[مقدار به دقیقه]) -> 0 | K16: =IF( OR(Table226810121416182022242628[[#This Row],[مقدار فعالیت]]=0,Table226810121416182022242628[[#This Row],[فعالیت پیش بینی شده]]=0),0,Table226810121416182022242628[[#This Row],[مقدار فعالیت]]-Table226810121416182022242628[[#This Row],[فعالیت پیش بینی شده]]) -> 0
C17: =IF(OR(A17="",B17=""),"",IF(B17>=A17,(B17-A17)*24*60,(B17-A17+1)*24*60)) | F17: =IF(OR(A17="",B17=""),"",MOD(B17-A17,1)) | H17: ورزش | J17: =SUMIF(Table1171921232527[موضوع],Table226810121416182022242628[[#This Row],[موضوع]],Table1171921232527[مقدار به دقیقه]) -> 0 | K17: =IF( OR(Table226810121416182022242628[[#This Row],[مقدار فعالیت]]=0,Table226810121416182022242628[[#This Row],[فعالیت پیش بینی شده]]=0),0,Table226810121416182022242628[[#This Row],[مقدار فعالیت]]-Table226810121416182022242628[[#This Row],[فعالیت پیش بینی شده]]) -> 0
C18: =IF(OR(A18="",B18=""),"",IF(B18>=A18,(B18-A18)*24*60,(B18-A18+1)*24*60)) | F18: =IF(OR(A18="",B18=""),"",MOD(B18-A18,1)) | H18: تفریح | J18: =SUMIF(Table1171921232527[موضوع],Table226810121416182022242628[[#This Row],[موضوع]],Table1171921232527[مقدار به دقیقه]) -> 0 | K18: =IF( OR(Table226810121416182022242628[[#This Row],[مقدار فعالیت]]=0,Table226810121416182022242628[[#This Row],[فعالیت پیش بینی شده]]=0),0,Table226810121416182022242628[[#This Row],[مقدار فعالیت]]-Table226810121416182022242628[[#This Row],[فعالیت پیش بینی شده]]) -> 0
C19: =IF(OR(A19="",B19=""),"",IF(B19>=A19,(B19-A19)*24*60,(B19-A19+1)*24*60)) | F19: =IF(OR(A19="",B19=""),"",MOD(B19-A19,1)) | H19: تدریس | J19: =SUMIF(Table1171921232527[موضوع],Table226810121416182022242628[[#This Row],[موضوع]],Table1171921232527[مقدار به دقیقه]) -> 0 | K19: =IF( OR(Table226810121416182022242628[[#This Row],[مقدار فعالیت]]=0,Table226810121416182022242628[[#This Row],[فعالیت پیش بینی شده]]=0),0,Table226810121416182022242628[[#This Row],[مقدار فعالیت]]-Table226810121416182022242628[[#This Row],[فعالیت پیش بینی شده]]) -> 0
C20: =IF(OR(A20="",B20=""),"",IF(B20>=A20,(B20-A20)*24*60,(B20-A20+1)*24*60)) | F20: =IF(OR(A20="",B20=""),"",MOD(B20-A20,1)) | H20: نظافت | J20: =SUMIF(Table1171921232527[موضوع],Table226810121416182022242628[[#This Row],[موضوع]],Table1171921232527[مقدار به دقیقه]) -> 0 | K20: =IF( OR(Table226810121416182022242628[[#This Row],[مقدار فعالیت]]=0,Table226810121416182022242628[[#This Row],[فعالیت پیش بینی شده]]=0),0,Table226810121416182022242628[[#This Row],[مقدار فعالیت]]-Table226810121416182022242628[[#This Row],[فعالیت پیش بینی شده]]) -> 0
C21: =IF(OR(A21="",B21=""),"",IF(B21>=A21,(B21-A21)*24*60,(B21-A21+1)*24*60)) | F21: =IF(OR(A21="",B21=""),"",MOD(B21-A21,1))
C22: =IF(OR(A22="",B22=""),"",IF(B22>=A22,(B22-A22)*24*60,(B22-A22+1)*24*60)) | F22: =IF(OR(A22="",B22=""),"",MOD(B22-A22,1))
C23: =IF(OR(A23="",B23=""),"",IF(B23>=A23,(B23-A23)*24*60,(B23-A23+1)*24*60)) | F23: =IF(OR(A23="",B23=""),"",MOD(B23-A23,1))
C24: =IF(OR(A24="",B24=""),"",IF(B24>=A24,(B24-A24)*24*60,(B24-A24+1)*24*60)) | F24: =IF(OR(A24="",B24=""),"",MOD(B24-A24,1))
C25: =IF(OR(A25="",B25=""),"",IF(B25>=A25,(B25-A25)*24*60,(B25-A25+1)*24*60)) | F25: =IF(OR(A25="",B25=""),"",MOD(B25-A25,1))
C26: =IF(OR(A26="",B26=""),"",IF(B26>=A26,(B26-A26)*24*60,(B26-A26+1)*24*60)) | F26: =IF(OR(A26="",B26=""),"",MOD(B26-A26,1))
C27: =IF(OR(A27="",B27=""),"",IF(B27>=A27,(B27-A27)*24*60,(B27-A27+1)*24*60)) | F27: =IF(OR(A27="",B27=""),"",MOD(B27-A27,1))
C28: =IF(OR(A28="",B28=""),"",IF(B28>=A28,(B28-A28)*24*60,(B28-A28+1)*24*60)) | F28: =IF(OR(A28="",B28=""),"",MOD(B28-A28,1))
C29: =IF(OR(A29="",B29=""),"",IF(B29>=A29,(B29-A29)*24*60,(B29-A29+1)*24*60)) | F29: =IF(OR(A29="",B29=""),"",MOD(B29-A29,1))
C30: =IF(OR(A30="",B30=""),"",IF(B30>=A30,(B30-A30)*24*60,(B30-A30+1)*24*60)) | F30: =IF(OR(A30="",B30=""),"",MOD(B30-A30,1))
C31: =IF(OR(A31="",B31=""),"",IF(B31>=A31,(B31-A31)*24*60,(B31-A31+1)*24*60)) | F31: =IF(OR(A31="",B31=""),"",MOD(B31-A31,1))
C32: =IF(OR(A32="",B32=""),"",IF(B32>=A32,(B32-A32)*24*60,(B32-A32+1)*24*60)) | F32: =IF(OR(A32="",B32=""),"",MOD(B32-A32,1))
... C39: =IF(OR(A39="",B39=""),"",IF(B39>=A39,(B39-A39)*24*60,(B39-A39+1)*24*60)) | F39: =IF(OR(A39="",B39=""),"",MOD(B39-A39,1))

Sheet یکشنبه
C5: گزارش روزانه
H7: موضوع | I7: فعالیت پیش بینی شده | J7: مقدار فعالیت | K7: میزان تفاوت
A8: یک شنبه | C8: 1404/8/1 | H8: خواب شب | J8: =SUMIF(Table117192123252725791113[موضوع],Table226810121416182022242628468101214[[#This Row],[موضوع]],Table117192123252725791113[مقدار به دقیقه]) -> 0 | K8: =IF( OR(Table226810121416182022242628468101214[[#This Row],[مقدار فعالیت]]=0,Table226810121416182022242628468101214[[#This Row],[فعالیت پیش بینی شده]]=0),0,Table226810121416182022242628468101214[[#This Row],[مقدار فعالیت]]-Table226810121416182022242628468101214[[#This Row],[فعالیت پیش بینی شده]]) -> 0
A9: ساعت شروع | B9: ساعت پایان | C9: مقدار به دقیقه | D9: موضوع | E9: توضیحات | F9: مقدار به ساعت | H9: غذا خوردن | J9: =SUMIF(Table117192123252725791113[موضوع],Table226810121416182022242628468101214[[#This Row],[موضوع]],Table117192123252725791113[مقدار به دقیقه]) -> 0 | K9: =IF( OR(Table226810121416182022242628468101214[[#This Row],[مقدار فعالیت]]=0,Table226810121416182022242628468101214[[#This Row],[فعالیت پیش بینی شده]]=0),0,Table226810121416182022242628468101214[[#This Row],[مقدار فعالیت]]-Table226810121416182022242628468101214[[#This Row],[فعالیت پیش بینی شده]]) -> 0
C10: =IF(OR(A10="",B10=""),"",IF(B10>=A10,(B10-A10)*24*60,(B10-A10+1)*24*60)) | F10: =IF(OR(A10="",B10=""),"",MOD(B10-A10,1)) | H10: رفت و آمد | J10: =SUMIF(Table117192123252725791113[موضوع],Table226810121416182022242628468101214[[#This Row],[موضوع]],Table117192123252725791113[مقدار به دقیقه]) -> 0 | K10: =IF( OR(Table226810121416182022242628468101214[[#This Row],[مقدار فعالیت]]=0,Table226810121416182022242628468101214[[#This Row],[فعالیت پیش بینی شده]]=0),0,Table226810121416182022242628468101214[[#This Row],[مقدار فعالیت]]-Table226810121416182022242628468101214[[#This Row],[فعالیت پیش بینی شده]]) -> 0
C11: =IF(OR(A11="",B11=""),"",IF(B11>=A11,(B11-A11)*24*60,(B11-A11+1)*24*60)) | F11: =IF(OR(A11="",B11=""),"",MOD(B11-A11,1)) | H11: پروژه | J11: =SUMIF(Table117192123252725791113[موضوع],Table226810121416182022242628468101214[[#This Row],[موضوع]],Table117192123252725791113[مقدار به دقیقه]) -> 0 | K11: =IF( OR(Table226810121416182022242628468101214[[#This Row],[مقدار فعالیت]]=0,Table226810121416182022242628468101214[[#This Row],[فعالیت پیش بینی شده]]=0),0,Table226810121416182022242628468101214[[#This Row],[مقدار فعالیت]]-Table226810121416182022242628468101214[[#This Row],[فعالیت پیش بینی شده]]) -> 0
C12: =IF(OR(A12="",B12=""),"",IF(B12>=A12,(B12-A12)*24*60,(B12-A12+1)*24*60)) | F12: =IF(OR(A12="",B12=""),"",MOD(B12-A12,1)) | H12: مطالعه | J12: =SUMIF(Table117192123252725791113[موضوع],Table226810121416182022242628468101214[[#This Row],[موضوع]],Table117192123252725791113[مقدار به دقیقه]) -> 0 | K12: =IF( OR(Table226810121416182022242628468101214[[#This Row],[مقدار فعالیت]]=0,Table226810121416182022242628468101214[[#This Row],[فعالیت پیش بینی شده]]=0),0,Table226810121416182022242628468101214[[#This Row],[مقدار فعالیت]]-Table226810121416182022242628468101214[[#This Row],[فعالیت پیش بینی شده]]) -> 0
C13: =IF(OR(A13="",B13=""),"",IF(B13>=A13,(B13-A13)*24*60,(B13-A13+1)*24*60)) | F13: =IF(OR(A13="",B13=""),"",MOD(B13-A13,1)) | H13: دیدن ویدیو آموزشی | J13: =SUMIF(Table117192123252725791113[موضوع],Table226810121416182022242628468101214[[#This Row],[موضوع]],Table117192123252725791113[مقدار به دقیقه]) -> 0 | K13: =IF( OR(Table226810121416182022242628468101214[[#This Row],[مقدار فعالیت]]=0,Table226810121416182022242628468101214[[#This Row],[فعالیت پیش بینی شده]]=0),0,Table226810121416182022242628468101214[[#This Row],[مقدار فعالیت]]-Table226810121416182022242628468101214[[#This Row],[فعالیت پیش بینی شده]]) -> 0
C14: =IF(OR(A14="",B14=""),"",IF(B14>=A14,(B14-A14)*24*60,(B14-A14+1)*24*60)) | F14: =IF(OR(A14="",B14=""),"",MOD(B14-A14,1)) | H14: مکتب | J14: =SUMIF(Table117192123252725791113[موضوع],Table226810121416182022242628468101214[[#This Row],[موضوع]],Table117192123252725791113[مقدار به دقیقه]) -> 0 | K14: =IF( OR(Table226810121416182022242628468101214[[#This Row],[مقدار فعالیت]]=0,Table226810121416182022242628468101214[[#This Row],[فعالیت پیش بینی شده]]=0),0,Table226810121416182022242628468101214[[#This Row],[مقدار فعالیت]]-Table226810121416182022242628468101214[[#This Row],[فعالیت پیش بینی شده]]) -> 0
C15: =IF(OR(A15="",B15=""),"",IF(B15>=A15,(B15-A15)*24*60,(B15-A15+1)*24*60)) | F15: =IF(OR(A15="",B15=""),"",MOD(B15-A15,1)) | H15: استراحت | J15: =SUMIF(Table117192123252725791113[موضوع],Table226810121416182022242628468101214[[#This Row],[موضوع]],Table117192123252725791113[مقدار به دقیقه]) -> 0 | K15: =IF( OR(Table226810121416182022242628468101214[[#This Row],[مقدار فعالیت]]=0,Table226810121416182022242628468101214[[#This Row],[فعالیت پیش بینی شده]]=0),0,Table226810121416182022242628468101214[[#This Row],[مقدار فعالیت]]-Table226810121416182022242628468101214[[#This Row],[فعالیت پیش بینی شده]]) -> 0
C16: =IF(OR(A16="",B16=""),"",IF(B16>=A16,(B16-A16)*24*60,(B16-A16+1)*24*60)) | F16: =IF(OR(A16="",B16=""),"",MOD(B16-A16,1)) | H16: متفرقه | J16: =SUMIF(Table117192123252725791113[موضوع],Table226810121416182022242628468101214[[#This Row],[موضوع]],Table117192123252725791113[مقدار به دقیقه]) -> 0 | K16: =IF( OR(Table226810121416182022242628468101214[[#This Row],[مقدار فعالیت]]=0,Table226810121416182022242628468101214[[#This Row],[فعالیت پیش بینی شده]]=0),0,Table226810121416182022242628468101214[[#This Row],[مقدار فعالیت]]-Table226810121416182022242628468101214[[#This Row],[فعالیت پیش بینی شده]]) -> 0
C17: =IF(OR(A17="",B17=""),"",IF(B17>=A17,(B17-A17)*24*60,(B17-A17+1)*24*60)) | F17: =IF(OR(A17="",B17=""),"",MOD(B17-A17,1)) | H17: ورزش | J17: =SUMIF(Table117192123252725791113[موضوع],Table226810121416182022242628468101214[[#This Row],[موضوع]],Table117192123252725791113[مقدار به دقیقه]) -> 0 | K17: =IF( OR(Table226810121416182022242628468101214[[#This Row],[مقدار فعالیت]]=0,Table226810121416182022242628468101214[[#This Row],[فعالیت پیش بینی شده]]=0),0,Table226810121416182022242628468101214[[#This Row],[مقدار فعالیت]]-Table226810121416182022242628468101214[[#This Row],[فعالیت پیش بینی شده]]) -> 0
C18: =IF(OR(A18="",B18=""),"",IF(B18>=A18,(B18-A18)*24*60,(B18-A18+1)*24*60)) | F18: =IF(OR(A18="",B18=""),"",MOD(B18-A18,1)) | H18: تفریح | J18: =SUMIF(Table117192123252725791113[موضوع],Table226810121416182022242628468101214[[#This Row],[موضوع]],Table117192123252725791113[مقدار به دقیقه]) -> 0 | K18: =IF( OR(Table226810121416182022242628468101214[[#This Row],[مقدار فعالیت]]=0,Table226810121416182022242628468101214[[#This Row],[فعالیت پیش بینی شده]]=0),0,Table226810121416182022242628468101214[[#This Row],[مقدار فعالیت]]-Table226810121416182022242628468101214[[#This Row],[فعالیت پیش بینی شده]]) -> 0
C19: =IF(OR(A19="",B19=""),"",IF(B19>=A19,(B19-A19)*24*60,(B19-A19+1)*24*60)) | F19: =IF(OR(A19="",B19=""),"",MOD(B19-A19,1))
C20: =IF(OR(A20="",B20=""),"",IF(B20>=A20,(B20-A20)*24*60,(B20-A20+1)*24*60)) | F20: =IF(OR(A20="",B20=""),"",MOD(B20-A20,1))
C21: =IF(OR(A21="",B21=""),"",IF(B21>=A21,(B21-A21)*24*60,(B21-A21+1)*24*60)) | F21: =IF(OR(A21="",B21=""),"",MOD(B21-A21,1))
C22: =IF(OR(A22="",B22=""),"",IF(B22>=A22,(B22-A22)*24*60,(B22-A22+1)*24*60)) | F22: =IF(OR(A22="",B22=""),"",MOD(B22-A22,1))
C23: =IF(OR(A23="",B23=""),"",IF(B23>=A23,(B23-A23)*24*60,(B23-A23+1)*24*60)) | F23: =IF(OR(A23="",B23=""),"",MOD(B23-A23,1))
C24: =IF(OR(A24="",B24=""),"",IF(B24>=A24,(B24-A24)*24*60,(B24-A24+1)*24*60)) | F24: =IF(OR(A24="",B24=""),"",MOD(B24-A24,1))
C25: =IF(OR(A25="",B25=""),"",IF(B25>=A25,(B25-A25)*24*60,(B25-A25+1)*24*60)) | F25: =IF(OR(A25="",B25=""),"",MOD(B25-A25,1))
C26: =IF(OR(A26="",B26=""),"",IF(B26>=A26,(B26-A26)*24*60,(B26-A26+1)*24*60)) | F26: =IF(OR(A26="",B26=""),"",MOD(B26-A26,1))
C27: =IF(OR(A27="",B27=""),"",IF(B27>=A27,(B27-A27)*24*60,(B27-A27+1)*24*60)) | F27: =IF(OR(A27="",B27=""),"",MOD(B27-A27,1))
C28: =IF(OR(A28="",B28=""),"",IF(B28>=A28,(B28-A28)*24*60,(B28-A28+1)*24*60)) | F28: =IF(OR(A28="",B28=""),"",MOD(B28-A28,1))
C29: =IF(OR(A29="",B29=""),"",IF(B29>=A29,(B29-A29)*24*60,(B29-A29+1)*24*60)) | F29: =IF(OR(A29="",B29=""),"",MOD(B29-A29,1))
C30: =IF(OR(A30="",B30=""),"",IF(B30>=A30,(B30-A30)*24*60,(B30-A30+1)*24*60)) | F30: =IF(OR(A30="",B30=""),"",MOD(B30-A30,1))
... C39: =IF(OR(A39="",B39=""),"",IF(B39>=A39,(B39-A39)*24*60,(B39-A39+1)*24*60)) | F39: =IF(OR(A39="",B39=""),"",MOD(B39-A39,1))

Sheet دو شنبه
C5: گزارش روزانه
H7: موضوع | I7: فعالیت پیش بینی شده | J7: مقدار فعالیت | K7: میزان تفاوت
A8: دو شنبه | C8: 1404/8/5 | H8: خواب شب | J8: =SUMIF(Table1171921232527257911[موضوع],Table2268101214161820222426284681012[[#This Row],[موضوع]],Table1171921232527257911[مقدار به دقیقه]) -> 390 | K8: =IF( OR(Table2268101214161820222426284681012[[#This Row],[مقدار فعالیت]]=0,Table2268101214161820222426284681012[[#This Row],[فعالیت پیش بینی شده]]=0),0,Table2268101214161820222426284681012[[#This Row],[مقدار فعالیت]]-Table2268101214161820222426284681012[[#This Row],[فعالیت پیش بینی شده]]) -> 0
A9: ساعت شروع | B9: ساعت پایان | C9: مقدار به دقیقه | D9: موضوع | E9: توضیحات | F9: مقدار به ساعت | H9: غذا خوردن | J9: =SUMIF(Table1171921232527257911[موضوع],Table2268101214161820222426284681012[[#This Row],[موضوع]],Table1171921232527257911[مقدار به دقیقه]) -> 150 | K9: =IF( OR(Table2268101214161820222426284681012[[#This Row],[مقدار فعالیت]]=0,Table2268101214161820222426284681012[[#This Row],[فعالیت پیش بینی شده]]=0),0,Table2268101214161820222426284681012[[#This Row],[مقدار فعالیت]]-Table2268101214161820222426284681012[[#This Row],[فعالیت پیش بینی شده]]) -> 0
A10: 0.9375 | B10: 0.20833333 | C10: =IF(OR(A10="",B10=""),"",IF(B10>=A10,(B10-A10)*24*60,(B10-A10+1)*24*60)) -> 390 | D10: خواب شب | F10: =IF(OR(A10="",B10=""),"",MOD(B10-A10,1)) -> 0.27083333 | H10: رفت و آمد | J10: =SUMIF(Table1171921232527257911[موضوع],Table2268101214161820222426284681012[[#This Row],[موضوع]],Table1171921232527257911[مقدار به دقیقه]) -> 150 | K10: =IF( OR(Table2268101214161820222426284681012[[#This Row],[مقدار فعالیت]]=0,Table2268101214161820222426284681012[[#This Row],[فعالیت پیش بینی شده]]=0),0,Table2268101214161820222426284681012[[#This Row],[مقدار فعالیت]]-Table2268101214161820222426284681012[[#This Row],[فعالیت پیش بینی شده]]) -> 0
A11: 0.20833333 | B11: 0.21527778 | C11: =IF(OR(A11="",B11=""),"",IF(B11>=A11,(B11-A11)*24*60,(B11-A11+1)*24*60)) -> 10 | D11: متفرقه | E11: نماز صبح | F11: =IF(OR(A11="",B11=""),"",MOD(B11-A11,1)) -> 0.0069444444 | H11: پروژه | J11: =SUMIF(Table1171921232527257911[موضوع],Table2268101214161820222426284681012[[#This Row],[موضوع]],Table1171921232527257911[مقدار به دقیقه]) -> 0 | K11: =IF( OR(Table2268101214161820222426284681012[[#This Row],[مقدار فعالیت]]=0,Table2268101214161820222426284681012[[#This Row],[فعالیت پیش بینی شده]]=0),0,Table2268101214161820222426284681012[[#This Row],[مقدار فعالیت]]-Table2268101214161820222426284681012[[#This Row],[فعالیت پیش بینی شده]]) -> 0
A12: 0.21527778 | B12: 0.27083333 | C12: =IF(OR(A12="",B12=""),"",IF(B12>=A12,(B12-A12)*24*60,(B12-A12+1)*24*60)) -> 80 | D12: متفرقه | E12: دوباره خوابیدم | F12: =IF(OR(A12="",B12=""),"",MOD(B12-A12,1)) -> 0.055555556 | H12: مطالعه | J12: =SUMIF(Table1171921232527257911[موضوع],Table2268101214161820222426284681012[[#This Row],[موضوع]],Table1171921232527257911[مقدار به دقیقه]) -> 0 | K12: =IF( OR(Table2268101214161820222426284681012[[#This Row],[مقدار فعالیت]]=0,Table2268101214161820222426284681012[[#This Row],[فعالیت پیش بینی شده]]=0),0,Table2268101214161820222426284681012[[#This Row],[مقدار فعالیت]]-Table2268101214161820222426284681012[[#This Row],[فعالیت پیش بینی شده]]) -> 0
A13: 0.27083333 | B13: 0.29166667 | C13: =IF(OR(A13="",B13=""),"",IF(B13>=A13,(B13-A13)*24*60,(B13-A13+1)*24*60)) -> 30 | D13: غذا خوردن | F13: =IF(OR(A13="",B13=""),"",MOD(B13-A13,1)) -> 0.020833333 | H13: دیدن ویدیو آموزشی | J13: =SUMIF(Table1171921232527257911[موضوع],Table2268101214161820222426284681012[[#This Row],[موضوع]],Table1171921232527257911[مقدار به دقیقه]) -> 255 | K13: =IF( OR(Table2268101214161820222426284681012[[#This Row],[مقدار فعالیت]]=0,Table2268101214161820222426284681012[[#This Row],[فعالیت پیش بینی شده]]=0),0,Table2268101214161820222426284681012[[#This Row],[مقدار فعالیت]]-Table2268101214161820222426284681012[[#This Row],[فعالیت پیش بینی شده]]) -> 0
A14: 0.29166667 | B14: 0.34027778 | C14: =IF(OR(A14="",B14=""),"",IF(B14>=A14,(B14-A14)*24*60,(B14-A14+1)*24*60)) -> 70 | D14: رفت و آمد | F14: =IF(OR(A14="",B14=""),"",MOD(B14-A14,1)) -> 0.048611111 | H14: مکتب | J14: =SUMIF(Table1171921232527257911[موضوع],Table2268101214161820222426284681012[[#This Row],[موضوع]],Table1171921232527257911[مقدار به دقیقه]) -> 0 | K14: =IF( OR(Table2268101214161820222426284681012[[#This Row],[مقدار فعالیت]]=0,Table2268101214161820222426284681012[[#This Row],[فعالیت پیش بینی شده]]=0),0,Table2268101214161820222426284681012[[#This Row],[مقدار فعالیت]]-Table2268101214161820222426284681012[[#This Row],[فعالیت پیش بینی شده]]) -> 0
A15: 0.34027778 | B15: 0.36111111 | C15: =IF(OR(A15="",B15=""),"",IF(B15>=A15,(B15-A15)*24*60,(B15-A15+1)*24*60)) -> 30 | D15: دیدن ویدیو آموزشی | F15: =IF(OR(A15="",B15=""),"",MOD(B15-A15,1)) -> 0.020833333 | H15: استراحت | J15: =SUMIF(Table1171921232527257911[موضوع],Table2268101214161820222426284681012[[#This Row],[موضوع]],Table1171921232527257911[مقدار به دقیقه]) -> 0 | K15: =IF( OR(Table2268101214161820222426284681012[[#This Row],[مقدار فعالیت]]=0,Table2268101214161820222426284681012[[#This Row],[فعالیت پیش بینی شده]]=0),0,Table2268101214161820222426284681012[[#This Row],[مقدار فعالیت]]-Table2268101214161820222426284681012[[#This Row],[فعالیت پیش بینی شده]]) -> 0
A16: 0.36111111 | B16: 0.41666667 | C16: =IF(OR(A16="",B16=""),"",IF(B16>=A16,(B16-A16)*24*60,(B16-A16+1)*24*60)) -> 80 | D16: متفرقه | E16: پاکاری اطاق کار استراحت | F16: =IF(OR(A16="",B16=""),"",MOD(B16-A16,1)) -> 0.055555556 | H16: متفرقه | J16: =SUMIF(Table1171921232527257911[موضوع],Table2268101214161820222426284681012[[#This Row],[موضوع]],Table1171921232527257911[مقدار به دقیقه]) -> 1727775 | K16: =IF( OR(Table2268101214161820222426284681012[[#This Row],[مقدار فعالیت]]=0,Table2268101214161820222426284681012[[#This Row],[فعالیت پیش بینی شده]]=0),0,Table2268101214161820222426284681012[[#This Row],[مقدار فعالیت]]-Table2268101214161820222426284681012[[#This Row],[فعالیت پیش بینی شده]]) -> 0
A17: 0.41666667 | B17: 0.47222222 | C17: =IF(OR(A17="",B17=""),"",IF(B17>=A17,(B17-A17)*24*60,(B17-A17+1)*24*60)) -> 80 | D17: رفت و آمد | F17: =IF(OR(A17="",B17=""),"",MOD(B17-A17,1)) -> 0.055555556 | H17: ورزش | J17: =SUMIF(Table1171921232527257911[موضوع],Table2268101214161820222426284681012[[#This Row],[موضوع]],Table1171921232527257911[مقدار به دقیقه]) -> 0 | K17: =IF( OR(Table2268101214161820222426284681012[[#This Row],[مقدار فعالیت]]=0,Table2268101214161820222426284681012[[#This Row],[فعالیت پیش بینی شده]]=0),0,Table2268101214161820222426284681012[[#This Row],[مقدار فعالیت]]-Table2268101214161820222426284681012[[#This Row],[فعالیت پیش بینی شده]]) -> 0
A18: 0.47222222 | B18: 1200 | C18: =IF(OR(A18="",B18=""),"",IF(B18>=A18,(B18-A18)*24*60,(B18-A18+1)*24*60)) -> 1727320 | D18: متفرقه | E18: صالون فوتبال رفتم و فوتبال تماشا کردم | F18: =IF(OR(A18="",B18=""),"",MOD(B18-A18,1)) -> 0.52777778 | H18: تفریح | J18: =SUMIF(Table1171921232527257911[موضوع],Table2268101214161820222426284681012[[#This Row],[موضوع]],Table1171921232527257911[مقدار به دقیقه]) -> 0 | K18: =IF( OR(Table2268101214161820222426284681012[[#This Row],[مقدار فعالیت]]=0,Table2268101214161820222426284681012[[#This Row],[فعالیت پیش بینی شده]]=0),0,Table2268101214161820222426284681012[[#This Row],[مقدار فعالیت]]-Table2268101214161820222426284681012[[#This Row],[فعالیت پیش بینی شده]]) -> 0
A19: 0.5 | B19: 0.54166667 | C19: =IF(OR(A19="",B19=""),"",IF(B19>=A19,(B19-A19)*24*60,(B19-A19+1)*24*60)) -> 60 | D19: غذا خوردن | F19: =IF(OR(A19="",B19=""),"",MOD(B19-A19,1)) -> 0.041666667
A20: 0.54166667 | B20: 0.55208333 | C20: =IF(OR(A20="",B20=""),"",IF(B20>=A20,(B20-A20)*24*60,(B20-A20+1)*24*60)) -> 15 | D20: متفرقه | E20: رفتم کتابخانه | F20: =IF(OR(A20="",B20=""),"",MOD(B20-A20,1)) -> 0.010416667
A21: 0.55208333 | B21: 0.70833333 | C21: =IF(OR(A21="",B21=""),"",IF(B21>=A21,(B21-A21)*24*60,(B21-A21+1)*24*60)) -> 225 | D21: دیدن ویدیو آموزشی | F21: =IF(OR(A21="",B21=""),"",MOD(B21-A21,1)) -> 0.15625
A22: 0.70833333 | B22: 0.75 | C22: =IF(OR(A22="",B22=""),"",IF(B22>=A22,(B22-A22)*24*60,(B22-A22+1)*24*60)) -> 60 | D22: متفرقه | E22: از پول خشک تا خانه پیاده روی کردم | F22: =IF(OR(A22="",B22=""),"",MOD(B22-A22,1)) -> 0.041666667
A23: 0.75 | B23: 0.83333333 | C23: =IF(OR(A23="",B23=""),"",IF(B23>=A23,(B23-A23)*24*60,(B23-A23+1)*24*60)) -> 120 | D23: متفرقه | E23: نماز مغرب و عشا چای و با برادر زاده ام در درس هایش کمک کردم | F23: =IF(OR(A23="",B23=""),"",MOD(B23-A23,1)) -> 0.083333333
A24: 0.83333333 | B24: 0.875 | C24: =IF(OR(A24="",B24=""),"",IF(B24>=A24,(B24-A24)*24*60,(B24-A24+1)*24*60)) -> 60 | D24: غذا خوردن | F24: =IF(OR(A24="",B24=""),"",MOD(B24-A24,1)) -> 0.041666667
A25: 0.875 | B25: 0.9375 | C25: =IF(OR(A25="",B25=""),"",IF(B25>=A25,(B25-A25)*24*60,(B25-A25+1)*24*60)) -> 90 | D25: متفرقه | E25: فیلم دیدم | F25: =IF(OR(A25="",B25=""),"",MOD(B25-A25,1)) -> 0.0625
C26: =IF(OR(A26="",B26=""),"",IF(B26>=A26,(B26-A26)*24*60,(B26-A26+1)*24*60)) | F26: =IF(OR(A26="",B26=""),"",MOD(B26-A26,1))
C27: =IF(OR(A27="",B27=""),"",IF(B27>=A27,(B27-A27)*24*60,(B27-A27+1)*24*60)) | F27: =IF(OR(A27="",B27=""),"",MOD(B27-A27,1))
C28: =IF(OR(A28="",B28=""),"",IF(B28>=A28,(B28-A28)*24*60,(B28-A28+1)*24*60)) | F28: =IF(OR(A28="",B28=""),"",MOD(B28-A28,1))
C29: =IF(OR(A29="",B29=""),"",IF(B29>=A29,(B29-A29)*24*60,(B29-A29+1)*24*60)) | F29: =IF(OR(A29="",B29=""),"",MOD(B29-A29,1))
C30: =IF(OR(A30="",B30=""),"",IF(B30>=A30,(B30-A30)*24*60,(B30-A30+1)*24*60)) | F30: =IF(OR(A30="",B30=""),"",MOD(B30-A30,1))
C31: =IF(OR(A31="",B31=""),"",IF(B31>=A31,(B31-A31)*24*60,(B31-A31+1)*24*60)) | F31: =IF(OR(A31="",B31=""),"",MOD(B31-A31,1))
C32: =IF(OR(A32="",B32=""),"",IF(B32>=A32,(B32-A32)*24*60,(B32-A32+1)*24*60)) | F32: =IF(OR(A32="",B32=""),"",MOD(B32-A32,1))
C33: =IF(OR(A33="",B33=""),"",IF(B33>=A33,(B33-A33)*24*60,(B33-A33+1)*24*60)) | F33: =IF(OR(A33="",B33=""),"",MOD(B33-A33,1))
C34: =IF(OR(A34="",B34=""),"",IF(B34>=A34,(B34-A34)*24*60,(B34-A34+1)*24*60)) | F34: =IF(OR(A34="",B34=""),"",MOD(B34-A34,1))
C35: =IF(OR(A35="",B35=""),"",IF(B35>=A35,(B35-A35)*24*60,(B35-A35+1)*24*60)) | F35: =IF(OR(A35="",B35=""),"",MOD(B35-A35,1))
C36: =IF(OR(A36="",B36=""),"",IF(B36>=A36,(B36-A36)*24*60,(B36-A36+1)*24*60)) | F36: =IF(OR(A36="",B36=""),"",MOD(B36-A36,1))
C37: =IF(OR(A37="",B37=""),"",IF(B37>=A37,(B37-A37)*24*60,(B37-A37+1)*24*60)) | F37: =IF(OR(A37="",B37=""),"",MOD(B37-A37,1))
... C39: =IF(OR(A39="",B39=""),"",IF(B39>=A39,(B39-A39)*24*60,(B39-A39+1)*24*60)) | F39: =IF(OR(A39="",B39=""),"",MOD(B39-A39,1))

Sheet سه شنبه
C5: گزارش روزانه
H7: موضوع | I7: فعالیت پیش بینی شده | J7: مقدار فعالیت | K7: میزان تفاوت
A8: سه شنبه | C8: 1404/8/1 | H8: خواب شب | J8: =SUMIF(Table11719212325272579[موضوع],Table22681012141618202224262846810[[#This Row],[موضوع]],Table11719212325272579[[#All],[مقدار به دقیقه]]) -> 0 | K8: =IF( OR(Table22681012141618202224262846810[[#This Row],[مقدار فعالیت]]=0,Table22681012141618202224262846810[[#This Row],[فعالیت پیش بینی شده]]=0),0,Table22681012141618202224262846810[[#This Row],[مقدار فعالیت]]-Table22681012141618202224262846810[[#This Row],[فعالیت پیش بینی شده]]) -> 0
A9: ساعت شروع | B9: ساعت پایان | C9: مقدار به دقیقه | D9: موضوع | E9: توضیحات | F9: مقدار به ساعت | H9: غذا خوردن | J9: =SUMIF(Table11719212325272579[موضوع],Table22681012141618202224262846810[[#This Row],[موضوع]],Table11719212325272579[مقدار به دقیقه]) -> 0 | K9: =IF( OR(Table22681012141618202224262846810[[#This Row],[مقدار فعالیت]]=0,Table22681012141618202224262846810[[#This Row],[فعالیت پیش بینی شده]]=0),0,Table22681012141618202224262846810[[#This Row],[مقدار فعالیت]]-Table22681012141618202224262846810[[#This Row],[فعالیت پیش بینی شده]]) -> 0
C10: =IF(OR(A10="",B10=""),"",IF(B10>=A10,(B10-A10)*24*60,(B10-A10+1)*24*60)) | F10: =IF(OR(A10="",B10=""),"",MOD(B10-A10,1)) | H10: رفت و آمد | J10: =SUMIF(Table11719212325272579[موضوع],Table22681012141618202224262846810[[#This Row],[موضوع]],Table11719212325272579[مقدار به دقیقه]) -> 0 | K10: =IF( OR(Table22681012141618202224262846810[[#This Row],[مقدار فعالیت]]=0,Table22681012141618202224262846810[[#This Row],[فعالیت پیش بینی شده]]=0),0,Table22681012141618202224262846810[[#This Row],[مقدار فعالیت]]-Table22681012141618202224262846810[[#This Row],[فعالیت پیش بینی شده]]) -> 0
C11: =IF(OR(A11="",B11=""),"",IF(B11>=A11,(B11-A11)*24*60,(B11-A11+1)*24*60)) | F11: =IF(OR(A11="",B11=""),"",MOD(B11-A11,1)) | H11: پروژه | J11: =SUMIF(Table11719212325272579[موضوع],Table22681012141618202224262846810[[#This Row],[موضوع]],Table11719212325272579[مقدار به دقیقه]) -> 0 | K11: =IF( OR(Table22681012141618202224262846810[[#This Row],[مقدار فعالیت]]=0,Table22681012141618202224262846810[[#This Row],[فعالیت پیش بینی شده]]=0),0,Table22681012141618202224262846810[[#This Row],[مقدار فعالیت]]-Table22681012141618202224262846810[[#This Row],[فعالیت پیش بینی شده]]) -> 0
C12: =IF(OR(A12="",B12=""),"",IF(B12>=A12,(B12-A12)*24*60,(B12-A12+1)*24*60)) | F12: =IF(OR(A12="",B12=""),"",MOD(B12-A12,1)) | H12: مطالعه | J12: =SUMIF(Table11719212325272579[موضوع],Table22681012141618202224262846810[[#This Row],[موضوع]],Table11719212325272579[مقدار به دقیقه]) -> 0 | K12: =IF( OR(Table22681012141618202224262846810[[#This Row],[مقدار فعالیت]]=0,Table22681012141618202224262846810[[#This Row],[فعالیت پیش بینی شده]]=0),0,Table22681012141618202224262846810[[#This Row],[مقدار فعالیت]]-Table22681012141618202224262846810[[#This Row],[فعالیت پیش بینی شده]]) -> 0
C13: =IF(OR(A13="",B13=""),"",IF(B13>=A13,(B13-A13)*24*60,(B13-A13+1)*24*60)) | F13: =IF(OR(A13="",B13=""),"",MOD(B13-A13,1)) | H13: دیدن ویدیو آموزشی | J13: =SUMIF(Table11719212325272579[موضوع],Table22681012141618202224262846810[[#This Row],[موضوع]],Table11719212325272579[مقدار به دقیقه]) -> 0 | K13: =IF( OR(Table22681012141618202224262846810[[#This Row],[مقدار فعالیت]]=0,Table22681012141618202224262846810[[#This Row],[فعالیت پیش بینی شده]]=0),0,Table22681012141618202224262846810[[#This Row],[مقدار فعالیت]]-Table22681012141618202224262846810[[#This Row],[فعالیت پیش بینی شده]]) -> 0
C14: =IF(OR(A14="",B14=""),"",IF(B14>=A14,(B14-A14)*24*60,(B14-A14+1)*24*60)) | F14: =IF(OR(A14="",B14=""),"",MOD(B14-A14,1)) | H14: مکتب | J14: =SUMIF(Table11719212325272579[موضوع],Table22681012141618202224262846810[[#This Row],[موضوع]],Table11719212325272579[مقدار به دقیقه]) -> 0 | K14: =IF( OR(Table22681012141618202224262846810[[#This Row],[مقدار فعالیت]]=0,Table22681012141618202224262846810[[#This Row],[فعالیت پیش بینی شده]]=0),0,Table22681012141618202224262846810[[#This Row],[مقدار فعالیت]]-Table22681012141618202224262846810[[#This Row],[فعالیت پیش بینی شده]]) -> 0
C15: =IF(OR(A15="",B15=""),"",IF(B15>=A15,(B15-A15)*24*60,(B15-A15+1)*24*60)) | F15: =IF(OR(A15="",B15=""),"",MOD(B15-A15,1)) | H15: استراحت | J15: =SUMIF(Table11719212325272579[موضوع],Table22681012141618202224262846810[[#This Row],[موضوع]],Table11719212325272579[مقدار به دقیقه]) -> 0 | K15: =IF( OR(Table22681012141618202224262846810[[#This Row],[مقدار فعالیت]]=0,Table22681012141618202224262846810[[#This Row],[فعالیت پیش بینی شده]]=0),0,Table22681012141618202224262846810[[#This Row],[مقدار فعالیت]]-Table22681012141618202224262846810[[#This Row],[فعالیت پیش بینی شده]]) -> 0
C16: =IF(OR(A16="",B16=""),"",IF(B16>=A16,(B16-A16)*24*60,(B16-A16+1)*24*60)) | F16: =IF(OR(A16="",B16=""),"",MOD(B16-A16,1)) | H16: متفرقه | J16: =SUMIF(Table11719212325272579[موضوع],Table22681012141618202224262846810[[#This Row],[موضوع]],Table11719212325272579[مقدار به دقیقه]) -> 0 | K16: =IF( OR(Table22681012141618202224262846810[[#This Row],[مقدار فعالیت]]=0,Table22681012141618202224262846810[[#This Row],[فعالیت پیش بینی شده]]=0),0,Table22681012141618202224262846810[[#This Row],[مقدار فعالیت]]-Table22681012141618202224262846810[[#This Row],[فعالیت پیش بینی شده]]) -> 0
C17: =IF(OR(A17="",B17=""),"",IF(B17>=A17,(B17-A17)*24*60,(B17-A17+1)*24*60)) | F17: =IF(OR(A17="",B17=""),"",MOD(B17-A17,1)) | H17: ورزش | J17: =SUMIF(Table11719212325272579[موضوع],Table22681012141618202224262846810[[#This Row],[موضوع]],Table11719212325272579[مقدار به دقیقه]) -> 0 | K17: =IF( OR(Table22681012141618202224262846810[[#This Row],[مقدار فعالیت]]=0,Table22681012141618202224262846810[[#This Row],[فعالیت پیش بینی شده]]=0),0,Table22681012141618202224262846810[[#This Row],[مقدار فعالیت]]-Table22681012141618202224262846810[[#This Row],[فعالیت پیش بینی شده]]) -> 0
C18: =IF(OR(A18="",B18=""),"",IF(B18>=A18,(B18-A18)*24*60,(B18-A18+1)*24*60)) | F18: =IF(OR(A18="",B18=""),"",MOD(B18-A18,1)) | H18: تفریح | J18: =SUMIF(Table11719212325272579[موضوع],Table22681012141618202224262846810[[#This Row],[موضوع]],Table11719212325272579[مقدار به دقیقه]) -> 0 | K18: =IF( OR(Table22681012141618202224262846810[[#This Row],[مقدار فعالیت]]=0,Table22681012141618202224262846810[[#This Row],[فعالیت پیش بینی شده]]=0),0,Table22681012141618202224262846810[[#This Row],[مقدار فعالیت]]-Table22681012141618202224262846810[[#This Row],[فعالیت پیش بینی شده]]) -> 0
C19: =IF(OR(A19="",B19=""),"",IF(B19>=A19,(B19-A19)*24*60,(B19-A19+1)*24*60)) | F19: =IF(OR(A19="",B19=""),"",MOD(B19-A19,1))
C20: =IF(OR(A20="",B20=""),"",IF(B20>=A20,(B20-A20)*24*60,(B20-A20+1)*24*60)) | F20: =IF(OR(A20="",B20=""),"",MOD(B20-A20,1))
C21: =IF(OR(A21="",B21=""),"",IF(B21>=A21,(B21-A21)*24*60,(B21-A21+1)*24*60)) | F21: =IF(OR(A21="",B21=""),"",MOD(B21-A21,1))
C22: =IF(OR(A22="",B22=""),"",IF(B22>=A22,(B22-A22)*24*60,(B22-A22+1)*24*60)) | F22: =IF(OR(A22="",B22=""),"",MOD(B22-A22,1))
C23: =IF(OR(A23="",B23=""),"",IF(B23>=A23,(B23-A23)*24*60,(B23-A23+1)*24*60)) | F23: =IF(OR(A23="",B23=""),"",MOD(B23-A23,1))
C24: =IF(OR(A24="",B24=""),"",IF(B24>=A24,(B24-A24)*24*60,(B24-A24+1)*24*60)) | F24: =IF(OR(A24="",B24=""),"",MOD(B24-A24,1))
C25: =IF(OR(A25="",B25=""),"",IF(B25>=A25,(B25-A25)*24*60,(B25-A25+1)*24*60)) | F25: =IF(OR(A25="",B25=""),"",MOD(B25-A25,1))
C26: =IF(OR(A26="",B26=""),"",IF(B26>=A26,(B26-A26)*24*60,(B26-A26+1)*24*60)) | F26: =IF(OR(A26="",B26=""),"",MOD(B26-A26,1))
C27: =IF(OR(A27="",B27=""),"",IF(B27>=A27,(B27-A27)*24*60,(B27-A27+1)*24*60)) | F27: =IF(OR(A27="",B27=""),"",MOD(B27-A27,1))
C28: =IF(OR(A28="",B28=""),"",IF(B28>=A28,(B28-A28)*24*60,(B28-A28+1)*24*60)) | F28: =IF(OR(A28="",B28=""),"",MOD(B28-A28,1))
C29: =IF(OR(A29="",B29=""),"",IF(B29>=A29,(B29-A29)*24*60,(B29-A29+1)*24*60)) | F29: =IF(OR(A29="",B29=""),"",MOD(B29-A29,1))
C30: =IF(OR(A30="",B30=""),"",IF(B30>=A30,(B30-A30)*24*60,(B30-A30+1)*24*60)) | F30: =IF(OR(A30="",B30=""),"",MOD(B30-A30,1))
... C39: =IF(OR(A39="",B39=""),"",IF(B39>=A39,(B39-A39)*24*60,(B39-A39+1)*24*60)) | F39: =IF(OR(A39="",B39=""),"",MOD(B39-A39,1))

Sheet چهار شنبه
C5: گزارش روزانه
H7: موضوع | I7: فعالیت پیش بینی شده | J7: مقدار فعالیت | K7: میزان تفاوت
A8: چهار شنبه | C8: 1404/8/1 | H8: خواب شب | J8: =SUMIF(Table1171921232527257[موضوع],Table226810121416182022242628468[[#This Row],[موضوع]],Table1171921232527257[مقدار به دقیقه]) -> 0 | K8: =IF( OR(Table226810121416182022242628468[[#This Row],[مقدار فعالیت]]=0,Table226810121416182022242628468[[#This Row],[فعالیت پیش بینی شده]]=0),0,Table226810121416182022242628468[[#This Row],[مقدار فعالیت]]-Table226810121416182022242628468[[#This Row],[فعالیت پیش بینی شده]]) -> 0
A9: ساعت شروع | B9: ساعت پایان | C9: مقدار به دقیقه | D9: موضوع | E9: توضیحات | F9: مقدار به ساعت | H9: غذا خوردن | J9: =SUMIF(Table1171921232527257[موضوع],Table226810121416182022242628468[[#This Row],[موضوع]],Table1171921232527257[مقدار به دقیقه]) -> 0 | K9: =IF( OR(Table226810121416182022242628468[[#This Row],[مقدار فعالیت]]=0,Table226810121416182022242628468[[#This Row],[فعالیت پیش بینی شده]]=0),0,Table226810121416182022242628468[[#This Row],[مقدار فعالیت]]-Table226810121416182022242628468[[#This Row],[فعالیت پیش بینی شده]]) -> 0
C10: =IF(OR(A10="",B10=""),"",IF(B10>=A10,(B10-A10)*24*60,(B10-A10+1)*24*60)) | F10: =IF(OR(A10="",B10=""),"",MOD(B10-A10,1)) | H10: رفت و آمد | J10: =SUMIF(Table1171921232527257[موضوع],Table226810121416182022242628468[[#This Row],[موضوع]],Table1171921232527257[مقدار به دقیقه]) -> 0 | K10: =IF( OR(Table226810121416182022242628468[[#This Row],[مقدار فعالیت]]=0,Table226810121416182022242628468[[#This Row],[فعالیت پیش بینی شده]]=0),0,Table226810121416182022242628468[[#This Row],[مقدار فعالیت]]-Table226810121416182022242628468[[#This Row],[فعالیت پیش بینی شده]]) -> 0
C11: =IF(OR(A11="",B11=""),"",IF(B11>=A11,(B11-A11)*24*60,(B11-A11+1)*24*60)) | F11: =IF(OR(A11="",B11=""),"",MOD(B11-A11,1)) | H11: پروژه | J11: =SUMIF(Table1171921232527257[موضوع],Table226810121416182022242628468[[#This Row],[موضوع]],Table1171921232527257[مقدار به دقیقه]) -> 0 | K11: =IF( OR(Table226810121416182022242628468[[#This Row],[مقدار فعالیت]]=0,Table226810121416182022242628468[[#This Row],[فعالیت پیش بینی شده]]=0),0,Table226810121416182022242628468[[#This Row],[مقدار فعالیت]]-Table226810121416182022242628468[[#This Row],[فعالیت پیش بینی شده]]) -> 0
C12: =IF(OR(A12="",B12=""),"",IF(B12>=A12,(B12-A12)*24*60,(B12-A12+1)*24*60)) | F12: =IF(OR(A12="",B12=""),"",MOD(B12-A12,1)) | H12: مطالعه | J12: =SUMIF(Table1171921232527257[موضوع],Table226810121416182022242628468[[#This Row],[موضوع]],Table1171921232527257[مقدار به دقیقه]) -> 0 | K12: =IF( OR(Table226810121416182022242628468[[#This Row],[مقدار فعالیت]]=0,Table226810121416182022242628468[[#This Row],[فعالیت پیش بینی شده]]=0),0,Table226810121416182022242628468[[#This Row],[مقدار فعالیت]]-Table226810121416182022242628468[[#This Row],[فعالیت پیش بینی شده]]) -> 0
C13: =IF(OR(A13="",B13=""),"",IF(B13>=A13,(B13-A13)*24*60,(B13-A13+1)*24*60)) | F13: =IF(OR(A13="",B13=""),"",MOD(B13-A13,1)) | H13: دیدن ویدیو آموزشی | J13: =SUMIF(Table1171921232527257[موضوع],Table226810121416182022242628468[[#This Row],[موضوع]],Table1171921232527257[مقدار به دقیقه]) -> 0 | K13: =IF( OR(Table226810121416182022242628468[[#This Row],[مقدار فعالیت]]=0,Table226810121416182022242628468[[#This Row],[فعالیت پیش بینی شده]]=0),0,Table226810121416182022242628468[[#This Row],[مقدار فعالیت]]-Table226810121416182022242628468[[#This Row],[فعالیت پیش بینی شده]]) -> 0
C14: =IF(OR(A14="",B14=""),"",IF(B14>=A14,(B14-A14)*24*60,(B14-A14+1)*24*60)) | F14: =IF(OR(A14="",B14=""),"",MOD(B14-A14,1)) | H14: مکتب | J14: =SUMIF(Table1171921232527257[موضوع],Table226810121416182022242628468[[#This Row],[موضوع]],Table1171921232527257[مقدار به دقیقه]) -> 0 | K14: =IF( OR(Table226810121416182022242628468[[#This Row],[مقدار فعالیت]]=0,Table226810121416182022242628468[[#This Row],[فعالیت پیش بینی شده]]=0),0,Table226810121416182022242628468[[#This Row],[مقدار فعالیت]]-Table226810121416182022242628468[[#This Row],[فعالیت پیش بینی شده]]) -> 0
C15: =IF(OR(A15="",B15=""),"",IF(B15>=A15,(B15-A15)*24*60,(B15-A15+1)*24*60)) | F15: =IF(OR(A15="",B15=""),"",MOD(B15-A15,1)) | H15: استراحت | J15: =SUMIF(Table1171921232527257[موضوع],Table226810121416182022242628468[[#This Row],[موضوع]],Table1171921232527257[مقدار به دقیقه]) -> 0 | K15: =IF( OR(Table226810121416182022242628468[[#This Row],[مقدار فعالیت]]=0,Table226810121416182022242628468[[#This Row],[فعالیت پیش بینی شده]]=0),0,Table226810121416182022242628468[[#This Row],[مقدار فعالیت]]-Table226810121416182022242628468[[#This Row],[فعالیت پیش بینی شده]]) -> 0
C16: =IF(OR(A16="",B16=""),"",IF(B16>=A16,(B16-A16)*24*60,(B16-A16+1)*24*60)) | F16: =IF(OR(A16="",B16=""),"",MOD(B16-A16,1)) | H16: متفرقه | J16: =SUMIF(Table1171921232527257[موضوع],Table226810121416182022242628468[[#This Row],[موضوع]],Table1171921232527257[مقدار به دقیقه]) -> 0 | K16: =IF( OR(Table226810121416182022242628468[[#This Row],[مقدار فعالیت]]=0,Table226810121416182022242628468[[#This Row],[فعالیت پیش بینی شده]]=0),0,Table226810121416182022242628468[[#This Row],[مقدار فعالیت]]-Table226810121416182022242628468[[#This Row],[فعالیت پیش بینی شده]]) -> 0
C17: =IF(OR(A17="",B17=""),"",IF(B17>=A17,(B17-A17)*24*60,(B17-A17+1)*24*60)) | F17: =IF(OR(A17="",B17=""),"",MOD(B17-A17,1)) | H17: ورزش | J17: =SUMIF(Table1171921232527257[موضوع],Table226810121416182022242628468[[#This Row],[موضوع]],Table1171921232527257[مقدار به دقیقه]) -> 0 | K17: =IF( OR(Table226810121416182022242628468[[#This Row],[مقدار فعالیت]]=0,Table226810121416182022242628468[[#This Row],[فعالیت پیش بینی شده]]=0),0,Table226810121416182022242628468[[#This Row],[مقدار فعالیت]]-Table226810121416182022242628468[[#This Row],[فعالیت پیش بینی شده]]) -> 0
C18: =IF(OR(A18="",B18=""),"",IF(B18>=A18,(B18-A18)*24*60,(B18-A18+1)*24*60)) | F18: =IF(OR(A18="",B18=""),"",MOD(B18-A18,1)) | H18: تفریح | J18: =SUMIF(Table1171921232527257[موضوع],Table226810121416182022242628468[[#This Row],[موضوع]],Table1171921232527257[مقدار به دقیقه]) -> 0 | K18: =IF( OR(Table226810121416182022242628468[[#This Row],[مقدار فعالیت]]=0,Table226810121416182022242628468[[#This Row],[فعالیت پیش بینی شده]]=0),0,Table226810121416182022242628468[[#This Row],[مقدار فعالیت]]-Table226810121416182022242628468[[#This Row],[فعالیت پیش بینی شده]]) -> 0
C19: =IF(OR(A19="",B19=""),"",IF(B19>=A19,(B19-A19)*24*60,(B19-A19+1)*24*60)) | F19: =IF(OR(A19="",B19=""),"",MOD(B19-A19,1))
C20: =IF(OR(A20="",B20=""),"",IF(B20>=A20,(B20-A20)*24*60,(B20-A20+1)*24*60)) | F20: =IF(OR(A20="",B20=""),"",MOD(B20-A20,1))
C21: =IF(OR(A21="",B21=""),"",IF(B21>=A21,(B21-A21)*24*60,(B21-A21+1)*24*60)) | F21: =IF(OR(A21="",B21=""),"",MOD(B21-A21,1))
C22: =IF(OR(A22="",B22=""),"",IF(B22>=A22,(B22-A22)*24*60,(B22-A22+1)*24*60)) | F22: =IF(OR(A22="",B22=""),"",MOD(B22-A22,1))
C23: =IF(OR(A23="",B23=""),"",IF(B23>=A23,(B23-A23)*24*60,(B23-A23+1)*24*60)) | F23: =IF(OR(A23="",B23=""),"",MOD(B23-A23,1))
C24: =IF(OR(A24="",B24=""),"",IF(B24>=A24,(B24-A24)*24*60,(B24-A24+1)*24*60)) | F24: =IF(OR(A24="",B24=""),"",MOD(B24-A24,1))
C25: =IF(OR(A25="",B25=""),"",IF(B25>=A25,(B25-A25)*24*60,(B25-A25+1)*24*60)) | F25: =IF(OR(A25="",B25=""),"",MOD(B25-A25,1))
C26: =IF(OR(A26="",B26=""),"",IF(B26>=A26,(B26-A26)*24*60,(B26-A26+1)*24*60)) | F26: =IF(OR(A26="",B26=""),"",MOD(B26-A26,1))
C27: =IF(OR(A27="",B27=""),"",IF(B27>=A27,(B27-A27)*24*60,(B27-A27+1)*24*60)) | F27: =IF(OR(A27="",B27=""),"",MOD(B27-A27,1))
C28: =IF(OR(A28="",B28=""),"",IF(B28>=A28,(B28-A28)*24*60,(B28-A28+1)*24*60)) | F28: =IF(OR(A28="",B28=""),"",MOD(B28-A28,1))
C29: =IF(OR(A29="",B29=""),"",IF(B29>=A29,(B29-A29)*24*60,(B29-A29+1)*24*60)) | F29: =IF(OR(A29="",B29=""),"",MOD(B29-A29,1))
C30: =IF(OR(A30="",B30=""),"",IF(B30>=A30,(B30-A30)*24*60,(B30-A30+1)*24*60)) | F30: =IF(OR(A30="",B30=""),"",MOD(B30-A30,1))
... C39: =IF(OR(A39="",B39=""),"",IF(B39>=A39,(B39-A39)*24*60,(B39-A39+1)*24*60)) | F39: =IF(OR(A39="",B39=""),"",MOD(B39-A39,1))

Sheet پنجشنبه
C5: گزارش روزانه
H7: موضوع | I7: فعالیت پیش بینی شده | J7: مقدار فعالیت | K7: میزان تفاوت
A8: پنجشنبه | C8: 1404/8/1 | H8: خواب شب | J8: =SUMIF(Table117192123252725[موضوع],Table22681012141618202224262846[[#This Row],[موضوع]],Table117192123252725[مقدار به دقیقه]) -> 0 | K8: =IF( OR(Table22681012141618202224262846[[#This Row],[مقدار فعالیت]]=0,Table22681012141618202224262846[[#This Row],[فعالیت پیش بینی شده]]=0),0,Table22681012141618202224262846[[#This Row],[مقدار فعالیت]]-Table22681012141618202224262846[[#This Row],[فعالیت پیش بینی شده]]) -> 0
A9: ساعت شروع | B9: ساعت پایان | C9: مقدار به دقیقه | D9: موضوع | E9: توضیحات | F9: مقدار به ساعت | H9: غذا خوردن | J9: =SUMIF(Table117192123252725[موضوع],Table22681012141618202224262846[[#This Row],[موضوع]],Table117192123252725[مقدار به دقیقه]) -> 0 | K9: =IF( OR(Table22681012141618202224262846[[#This Row],[مقدار فعالیت]]=0,Table22681012141618202224262846[[#This Row],[فعالیت پیش بینی شده]]=0),0,Table22681012141618202224262846[[#This Row],[مقدار فعالیت]]-Table22681012141618202224262846[[#This Row],[فعالیت پیش بینی شده]]) -> 0
C10: =IF(OR(A10="",B10=""),"",IF(B10>=A10,(B10-A10)*24*60,(B10-A10+1)*24*60)) | F10: =IF(OR(A10="",B10=""),"",MOD(B10-A10,1)) | H10: رفت و آمد | J10: =SUMIF(Table117192123252725[موضوع],Table22681012141618202224262846[[#This Row],[موضوع]],Table117192123252725[مقدار به دقیقه]) -> 0 | K10: =IF( OR(Table22681012141618202224262846[[#This Row],[مقدار فعالیت]]=0,Table22681012141618202224262846[[#This Row],[فعالیت پیش بینی شده]]=0),0,Table22681012141618202224262846[[#This Row],[مقدار فعالیت]]-Table22681012141618202224262846[[#This Row],[فعالیت پیش بینی شده]]) -> 0
C11: =IF(OR(A11="",B11=""),"",IF(B11>=A11,(B11-A11)*24*60,(B11-A11+1)*24*60)) | F11: =IF(OR(A11="",B11=""),"",MOD(B11-A11,1)) | H11: پروژه | J11: =SUMIF(Table117192123252725[موضوع],Table22681012141618202224262846[[#This Row],[موضوع]],Table117192123252725[مقدار به دقیقه]) -> 0 | K11: =IF( OR(Table22681012141618202224262846[[#This Row],[مقدار فعالیت]]=0,Table22681012141618202224262846[[#This Row],[فعالیت پیش بینی شده]]=0),0,Table22681012141618202224262846[[#This Row],[مقدار فعالیت]]-Table22681012141618202224262846[[#This Row],[فعالیت پیش بینی شده]]) -> 0
C12: =IF(OR(A12="",B12=""),"",IF(B12>=A12,(B12-A12)*24*60,(B12-A12+1)*24*60)) | F12: =IF(OR(A12="",B12=""),"",MOD(B12-A12,1)) | H12: مطالعه | J12: =SUMIF(Table117192123252725[موضوع],Table22681012141618202224262846[[#This Row],[موضوع]],Table117192123252725[مقدار به دقیقه]) -> 0 | K12: =IF( OR(Table22681012141618202224262846[[#This Row],[مقدار فعالیت]]=0,Table22681012141618202224262846[[#This Row],[فعالیت پیش بینی شده]]=0),0,Table22681012141618202224262846[[#This Row],[مقدار فعالیت]]-Table22681012141618202224262846[[#This Row],[فعالیت پیش بینی شده]]) -> 0
C13: =IF(OR(A13="",B13=""),"",IF(B13>=A13,(B13-A13)*24*60,(B13-A13+1)*24*60)) | F13: =IF(OR(A13="",B13=""),"",MOD(B13-A13,1)) | H13: دیدن ویدیو آموزشی | J13: =SUMIF(Table117192123252725[موضوع],Table22681012141618202224262846[[#This Row],[موضوع]],Table117192123252725[مقدار به دقیقه]) -> 0 | K13: =IF( OR(Table22681012141618202224262846[[#This Row],[مقدار فعالیت]]=0,Table22681012141618202224262846[[#This Row],[فعالیت پیش بینی شده]]=0),0,Table22681012141618202224262846[[#This Row],[مقدار فعالیت]]-Table22681012141618202224262846[[#This Row],[فعالیت پیش بینی شده]]) -> 0
C14: =IF(OR(A14="",B14=""),"",IF(B14>=A14,(B14-A14)*24*60,(B14-A14+1)*24*60)) | F14: =IF(OR(A14="",B14=""),"",MOD(B14-A14,1)) | H14: مکتب | J14: =SUMIF(Table117192123252725[موضوع],Table22681012141618202224262846[[#This Row],[موضوع]],Table117192123252725[مقدار به دقیقه]) -> 0 | K14: =IF( OR(Table22681012141618202224262846[[#This Row],[مقدار فعالیت]]=0,Table22681012141618202224262846[[#This Row],[فعالیت پیش بینی شده]]=0),0,Table22681012141618202224262846[[#This Row],[مقدار فعالیت]]-Table22681012141618202224262846[[#This Row],[فعالیت پیش بینی شده]]) -> 0
C15: =IF(OR(A15="",B15=""),"",IF(B15>=A15,(B15-A15)*24*60,(B15-A15+1)*24*60)) | F15: =IF(OR(A15="",B15=""),"",MOD(B15-A15,1)) | H15: استراحت | J15: =SUMIF(Table117192123252725[موضوع],Table22681012141618202224262846[[#This Row],[موضوع]],Table117192123252725[مقدار به دقیقه]) -> 0 | K15: =IF( OR(Table22681012141618202224262846[[#This Row],[مقدار فعالیت]]=0,Table22681012141618202224262846[[#This Row],[فعالیت پیش بینی شده]]=0),0,Table22681012141618202224262846[[#This Row],[مقدار فعالیت]]-Table22681012141618202224262846[[#This Row],[فعالیت پیش بینی شده]]) -> 0
C16: =IF(OR(A16="",B16=""),"",IF(B16>=A16,(B16-A16)*24*60,(B16-A16+1)*24*60)) | F16: =IF(OR(A16="",B16=""),"",MOD(B16-A16,1)) | H16: متفرقه | J16: =SUMIF(Table117192123252725[موضوع],Table22681012141618202224262846[[#This Row],[موضوع]],Table117192123252725[مقدار به دقیقه]) -> 0 | K16: =IF( OR(Table22681012141618202224262846[[#This Row],[مقدار فعالیت]]=0,Table22681012141618202224262846[[#This Row],[فعالیت پیش بینی شده]]=0),0,Table22681012141618202224262846[[#This Row],[مقدار فعالیت]]-Table22681012141618202224262846[[#This Row],[فعالیت پیش بینی شده]]) -> 0
C17: =IF(OR(A17="",B17=""),"",IF(B17>=A17,(B17-A17)*24*60,(B17-A17+1)*24*60)) | F17: =IF(OR(A17="",B17=""),"",MOD(B17-A17,1)) | H17: ورزش | J17: =SUMIF(Table117192123252725[موضوع],Table22681012141618202224262846[[#This Row],[موضوع]],Table117192123252725[مقدار به دقیقه]) -> 0 | K17: =IF( OR(Table22681012141618202224262846[[#This Row],[مقدار فعالیت]]=0,Table22681012141618202224262846[[#This Row],[فعالیت پیش بینی شده]]=0),0,Table22681012141618202224262846[[#This Row],[مقدار فعالیت]]-Table22681012141618202224262846[[#This Row],[فعالیت پیش بینی شده]]) -> 0
C18: =IF(OR(A18="",B18=""),"",IF(B18>=A18,(B18-A18)*24*60,(B18-A18+1)*24*60)) | F18: =IF(OR(A18="",B18=""),"",MOD(B18-A18,1)) | H18: تفریح | J18: =SUMIF(Table117192123252725[موضوع],Table22681012141618202224262846[[#This Row],[موضوع]],Table117192123252725[مقدار به دقیقه]) -> 0 | K18: =IF( OR(Table22681012141618202224262846[[#This Row],[مقدار فعالیت]]=0,Table22681012141618202224262846[[#This Row],[فعالیت پیش بینی شده]]=0),0,Table22681012141618202224262846[[#This Row],[مقدار فعالیت]]-Table22681012141618202224262846[[#This Row],[فعالیت پیش بینی شده]]) -> 0
C19: =IF(OR(A19="",B19=""),"",IF(B19>=A19,(B19-A19)*24*60,(B19-A19+1)*24*60)) | F19: =IF(OR(A19="",B19=""),"",MOD(B19-A19,1))
C20: =IF(OR(A20="",B20=""),"",IF(B20>=A20,(B20-A20)*24*60,(B20-A20+1)*24*60)) | F20: =IF(OR(A20="",B20=""),"",MOD(B20-A20,1))
C21: =IF(OR(A21="",B21=""),"",IF(B21>=A21,(B21-A21)*24*60,(B21-A21+1)*24*60)) | F21: =IF(OR(A21="",B21=""),"",MOD(B21-A21,1))
C22: =IF(OR(A22="",B22=""),"",IF(B22>=A22,(B22-A22)*24*60,(B22-A22+1)*24*60)) | F22: =IF(OR(A22="",B22=""),"",MOD(B22-A22,1))
C23: =IF(OR(A23="",B23=""),"",IF(B23>=A23,(B23-A23)*24*60,(B23-A23+1)*24*60)) | F23: =IF(OR(A23="",B23=""),"",MOD(B23-A23,1))
C24: =IF(OR(A24="",B24=""),"",IF(B24>=A24,(B24-A24)*24*60,(B24-A24+1)*24*60)) | F24: =IF(OR(A24="",B24=""),"",MOD(B24-A24,1))
C25: =IF(OR(A25="",B25=""),"",IF(B25>=A25,(B25-A25)*24*60,(B25-A25+1)*24*60)) | F25: =IF(OR(A25="",B25=""),"",MOD(B25-A25,1))
C26: =IF(OR(A26="",B26=""),"",IF(B26>=A26,(B26-A26)*24*60,(B26-A26+1)*24*60)) | F26: =IF(OR(A26="",B26=""),"",MOD(B26-A26,1))
C27: =IF(OR(A27="",B27=""),"",IF(B27>=A27,(B27-A27)*24*60,(B27-A27+1)*24*60)) | F27: =IF(OR(A27="",B27=""),"",MOD(B27-A27,1))
C28: =IF(OR(A28="",B28=""),"",IF(B28>=A28,(B28-A28)*24*60,(B28-A28+1)*24*60)) | F28: =IF(OR(A28="",B28=""),"",MOD(B28-A28,1))
C29: =IF(OR(A29="",B29=""),"",IF(B29>=A29,(B29-A29)*24*60,(B29-A29+1)*24*60)) | F29: =IF(OR(A29="",B29=""),"",MOD(B29-A29,1))
C30: =IF(OR(A30="",B30=""),"",IF(B30>=A30,(B30-A30)*24*60,(B30-A30+1)*24*60)) | F30: =IF(OR(A30="",B30=""),"",MOD(B30-A30,1))
... C39: =IF(OR(A39="",B39=""),"",IF(B39>=A39,(B39-A39)*24*60,(B39-A39+1)*24*60)) | F39: =IF(OR(A39="",B39=""),"",MOD(B39-A39,1))

Sheet جمعه
C5: گزارش روزانه
H7: موضوع | I7: فعالیت پیش بینی شده | J7: مقدار فعالیت | K7: میزان تفاوت
A8: جمعه | C8: 1404/8/1 | H8: خواب شب | J8: =SUMIF(Table11719212325272[موضوع],Table2268101214161820222426284[[#This Row],[موضوع]],Table11719212325272[مقدار به دقیقه]) -> 0 | K8: =IF( OR(Table2268101214161820222426284[[#This Row],[مقدار فعالیت]]=0,Table2268101214161820222426284[[#This Row],[فعالیت پیش بینی شده]]=0),0,Table2268101214161820222426284[[#This Row],[مقدار فعالیت]]-Table2268101214161820222426284[[#This Row],[فعالیت پیش بینی شده]]) -> 0
A9: ردیف | B9: ساعت | C9: مقدار به دقیقه | D9: موضوع | E9: توضیحات | F9: مقدار به ساعت | H9: غذا خوردن | J9: =SUMIF(Table11719212325272[موضوع],Table2268101214161820222426284[[#This Row],[موضوع]],Table11719212325272[مقدار به دقیقه]) -> 0 | K9: =IF( OR(Table2268101214161820222426284[[#This Row],[مقدار فعالیت]]=0,Table2268101214161820222426284[[#This Row],[فعالیت پیش بینی شده]]=0),0,Table2268101214161820222426284[[#This Row],[مقدار فعالیت]]-Table2268101214161820222426284[[#This Row],[فعالیت پیش بینی شده]]) -> 0
C10: =IF(OR(A10="",B10=""),"",IF(B10>=A10,(B10-A10)*24*60,(B10-A10+1)*24*60)) | F10: =IF(OR(A10="",B10=""),"",MOD(B10-A10,1)) | H10: رفت و آمد | J10: =SUMIF(Table11719212325272[موضوع],Table2268101214161820222426284[[#This Row],[موضوع]],Table11719212325272[مقدار به دقیقه]) -> 0 | K10: =IF( OR(Table2268101214161820222426284[[#This Row],[مقدار فعالیت]]=0,Table2268101214161820222426284[[#This Row],[فعالیت پیش بینی شده]]=0),0,Table2268101214161820222426284[[#This Row],[مقدار فعالیت]]-Table2268101214161820222426284[[#This Row],[فعالیت پیش بینی شده]]) -> 0
C11: =IF(OR(A11="",B11=""),"",IF(B11>=A11,(B11-A11)*24*60,(B11-A11+1)*24*60)) | F11: =IF(OR(A11="",B11=""),"",MOD(B11-A11,1)) | H11: پروژه | J11: =SUMIF(Table11719212325272[موضوع],Table2268101214161820222426284[[#This Row],[موضوع]],Table11719212325272[مقدار به دقیقه]) -> 0 | K11: =IF( OR(Table2268101214161820222426284[[#This Row],[مقدار فعالیت]]=0,Table2268101214161820222426284[[#This Row],[فعالیت پیش بینی شده]]=0),0,Table2268101214161820222426284[[#This Row],[مقدار فعالیت]]-Table2268101214161820222426284[[#This Row],[فعالیت پیش بینی شده]]) -> 0
C12: =IF(OR(A12="",B12=""),"",IF(B12>=A12,(B12-A12)*24*60,(B12-A12+1)*24*60)) | F12: =IF(OR(A12="",B12=""),"",MOD(B12-A12,1)) | H12: مطالعه | J12: =SUMIF(Table11719212325272[موضوع],Table2268101214161820222426284[[#This Row],[موضوع]],Table11719212325272[مقدار به دقیقه]) -> 0 | K12: =IF( OR(Table2268101214161820222426284[[#This Row],[مقدار فعالیت]]=0,Table2268101214161820222426284[[#This Row],[فعالیت پیش بینی شده]]=0),0,Table2268101214161820222426284[[#This Row],[مقدار فعالیت]]-Table2268101214161820222426284[[#This Row],[فعالیت پیش بینی شده]]) -> 0
C13: =IF(OR(A13="",B13=""),"",IF(B13>=A13,(B13-A13)*24*60,(B13-A13+1)*24*60)) | F13: =IF(OR(A13="",B13=""),"",MOD(B13-A13,1)) | H13: دیدن ویدیو آموزشی | J13: =SUMIF(Table11719212325272[موضوع],Table2268101214161820222426284[[#This Row],[موضوع]],Table11719212325272[مقدار به دقیقه]) -> 0 | K13: =IF( OR(Table2268101214161820222426284[[#This Row],[مقدار فعالیت]]=0,Table2268101214161820222426284[[#This Row],[فعالیت پیش بینی شده]]=0),0,Table2268101214161820222426284[[#This Row],[مقدار فعالیت]]-Table2268101214161820222426284[[#This Row],[فعالیت پیش بینی شده]]) -> 0
C14: =IF(OR(A14="",B14=""),"",IF(B14>=A14,(B14-A14)*24*60,(B14-A14+1)*24*60)) | F14: =IF(OR(A14="",B14=""),"",MOD(B14-A14,1)) | H14: مکتب | J14: =SUMIF(Table11719212325272[موضوع],Table2268101214161820222426284[[#This Row],[موضوع]],Table11719212325272[مقدار به دقیقه]) -> 0 | K14: =IF( OR(Table2268101214161820222426284[[#This Row],[مقدار فعالیت]]=0,Table2268101214161820222426284[[#This Row],[فعالیت پیش بینی شده]]=0),0,Table2268101214161820222426284[[#This Row],[مقدار فعالیت]]-Table2268101214161820222426284[[#This Row],[فعالیت پیش بینی شده]]) -> 0
C15: =IF(OR(A15="",B15=""),"",IF(B15>=A15,(B15-A15)*24*60,(B15-A15+1)*24*60)) | F15: =IF(OR(A15="",B15=""),"",MOD(B15-A15,1)) | H15: استراحت | J15: =SUMIF(Table11719212325272[موضوع],Table2268101214161820222426284[[#This Row],[موضوع]],Table11719212325272[مقدار به دقیقه]) -> 0 | K15: =IF( OR(Table2268101214161820222426284[[#This Row],[مقدار فعالیت]]=0,Table2268101214161820222426284[[#This Row],[فعالیت پیش بینی شده]]=0),0,Table2268101214161820222426284[[#This Row],[مقدار فعالیت]]-Table2268101214161820222426284[[#This Row],[فعالیت پیش بینی شده]]) -> 0
C16: =IF(OR(A16="",B16=""),"",IF(B16>=A16,(B16-A16)*24*60,(B16-A16+1)*24*60)) | F16: =IF(OR(A16="",B16=""),"",MOD(B16-A16,1)) | H16: متفرقه | J16: =SUMIF(Table11719212325272[موضوع],Table2268101214161820222426284[[#This Row],[موضوع]],Table11719212325272[مقدار به دقیقه]) -> 0 | K16: =IF( OR(Table2268101214161820222426284[[#This Row],[مقدار فعالیت]]=0,Table2268101214161820222426284[[#This Row],[فعالیت پیش بینی شده]]=0),0,Table2268101214161820222426284[[#This Row],[مقدار فعالیت]]-Table2268101214161820222426284[[#This Row],[فعالیت پیش بینی شده]]) -> 0
C17: =IF(OR(A17="",B17=""),"",IF(B17>=A17,(B17-A17)*24*60,(B17-A17+1)*24*60)) | F17: =IF(OR(A17="",B17=""),"",MOD(B17-A17,1)) | H17: ورزش | J17: =SUMIF(Table11719212325272[موضوع],Table2268101214161820222426284[[#This Row],[موضوع]],Table11719212325272[مقدار به دقیقه]) -> 0 | K17: =IF( OR(Table2268101214161820222426284[[#This Row],[مقدار فعالیت]]=0,Table2268101214161820222426284[[#This Row],[فعالیت پیش بینی شده]]=0),0,Table2268101214161820222426284[[#This Row],[مقدار فعالیت]]-Table2268101214161820222426284[[#This Row],[فعالیت پیش بینی شده]]) -> 0
C18: =IF(OR(A18="",B18=""),"",IF(B18>=A18,(B18-A18)*24*60,(B18-A18+1)*24*60)) | F18: =IF(OR(A18="",B18=""),"",MOD(B18-A18,1)) | H18: تفریح | J18: =SUMIF(Table11719212325272[موضوع],Table2268101214161820222426284[[#This Row],[موضوع]],Table11719212325272[مقدار به دقیقه]) -> 0 | K18: =IF( OR(Table2268101214161820222426284[[#This Row],[مقدار فعالیت]]=0,Table2268101214161820222426284[[#This Row],[فعالیت پیش بینی شده]]=0),0,Table2268101214161820222426284[[#This Row],[مقدار فعالیت]]-Table2268101214161820222426284[[#This Row],[فعالیت پیش بینی شده]]) -> 0
C19: =IF(OR(A19="",B19=""),"",IF(B19>=A19,(B19-A19)*24*60,(B19-A19+1)*24*60)) | F19: =IF(OR(A19="",B19=""),"",MOD(B19-A19,1))
C20: =IF(OR(A20="",B20=""),"",IF(B20>=A20,(B20-A20)*24*60,(B20-A20+1)*24*60)) | F20: =IF(OR(A20="",B20=""),"",MOD(B20-A20,1))
C21: =IF(OR(A21="",B21=""),"",IF(B21>=A21,(B21-A21)*24*60,(B21-A21+1)*24*60)) | F21: =IF(OR(A21="",B21=""),"",MOD(B21-A21,1))
C22: =IF(OR(A22="",B22=""),"",IF(B22>=A22,(B22-A22)*24*60,(B22-A22+1)*24*60)) | F22: =IF(OR(A22="",B22=""),"",MOD(B22-A22,1))
C23: =IF(OR(A23="",B23=""),"",IF(B23>=A23,(B23-A23)*24*60,(B23-A23+1)*24*60)) | F23: =IF(OR(A23="",B23=""),"",MOD(B23-A23,1))
C24: =IF(OR(A24="",B24=""),"",IF(B24>=A24,(B24-A24)*24*60,(B24-A24+1)*24*60)) | F24: =IF(OR(A24="",B24=""),"",MOD(B24-A24,1))
C25: =IF(OR(A25="",B25=""),"",IF(B25>=A25,(B25-A25)*24*60,(B25-A25+1)*24*60)) | F25: =IF(OR(A25="",B25=""),"",MOD(B25-A25,1))
C26: =IF(OR(A26="",B26=""),"",IF(B26>=A26,(B26-A26)*24*60,(B26-A26+1)*24*60)) | F26: =IF(OR(A26="",B26=""),"",MOD(B26-A26,1))
C27: =IF(OR(A27="",B27=""),"",IF(B27>=A27,(B27-A27)*24*60,(B27-A27+1)*24*60)) | F27: =IF(OR(A27="",B27=""),"",MOD(B27-A27,1))
C28: =IF(OR(A28="",B28=""),"",IF(B28>=A28,(B28-A28)*24*60,(B28-A28+1)*24*60)) | F28: =IF(OR(A28="",B28=""),"",MOD(B28-A28,1))
C29: =IF(OR(A29="",B29=""),"",IF(B29>=A29,(B29-A29)*24*60,(B29-A29+1)*24*60)) | F29: =IF(OR(A29="",B29=""),"",MOD(B29-A29,1))
C30: =IF(OR(A30="",B30=""),"",IF(B30>=A30,(B30-A30)*24*60,(B30-A30+1)*24*60)) | F30: =IF(OR(A30="",B30=""),"",MOD(B30-A30,1))
... C39: =IF(OR(A39="",B39=""),"",IF(B39>=A39,(B39-A39)*24*60,(B39-A39+1)*24*60)) | F39: =IF(OR(A39="",B39=""),"",MOD(B39-A39,1))

Sheet داده ها
E3: موضوع | F3: فعالیت پیش بینی شده | G3: مقدار فعالیت | H3: میزان تفاوت
E4: خواب شب | F4: =SUM(شنبه!I8,یکشنبه!I8,'دو شنبه'!I8,'سه شنبه'!I8+جمعه!I8,'چهار شنبه'!I8+پنجشنبه!I8) -> 0 | G4: =SUM(شنبه!J8,یکشنبه!J8,'دو شنبه'!J8+جمعه!J8,'سه شنبه'!J8+پنجشنبه!J8,'چهار شنبه'!J8) -> 390 | H4: =IF( OR(Table8[[#This Row],[مقدار فعالیت]]=0,Table8[[#This Row],[فعالیت پیش بینی شده]]=0),0,Table8[[#This Row],[مقدار فعالیت]]-Table8[[#This Row],[فعالیت پیش بینی شده]]) -> 0 | K4: به دقیقه | L4: به ساعت
E5: غذا خوردن | F5: =SUM(شنبه!I9,یکشنبه!I9,'دو شنبه'!I9,'سه شنبه'!I9+جمعه!I9,'چهار شنبه'!I9+پنجشنبه!I9) -> 0 | G5: =SUM(شنبه!J9,یکشنبه!J9,'دو شنبه'!J9+جمعه!J9,'سه شنبه'!J9+پنجشنبه!J9,'چهار شنبه'!J9) -> 150 | H5: =IF( OR(Table8[[#This Row],[مقدار فعالیت]]=0,Table8[[#This Row],[فعالیت پیش بینی شده]]=0),0,Table8[[#This Row],[مقدار فعالیت]]-Table8[[#This Row],[فعالیت پیش بینی شده]]) -> 0 | I5: جمع دقایق پیش بینی شده | K5: =SUM(Table8[فعالیت پیش بینی شده]) -> 0 | L5: =INT(SUM(Table8[فعالیت پیش بینی شده])/60) & " ساعت " & MOD(SUM(Table8[فعالیت پیش بینی شده]),60) & " دقیقه" -> 0 ساعت 0 دقیقه
